// const process = require('process');

process.on('beforeExit', () => {
    console.log('Kliz, El proceso va a terminar');
});

// process.on('')

process.on('exit', () => {
    console.log('Kliz, El proceso terminÃ³');
    setTimeout(() => {
        console.log('Esto no se va a ver nunca');
    }, 0);
});

setTimeout(() => {
    console.log('Esto si se va a ver nunca');
}, 0);

process.on('uncaughtException', (err, origen) => {
    console.error('Vaya se nos ha olvidado capturar un error');
    setTimeout(() => {
        console.log('Esto viene desde las excepciones');
    }, 0);
});

funcionQueNoExiste();

console.log('Esto si el error no se recoge, no sale');